Workbook

Sheet Instruments
A1: curve | B1: type | C1: subtype | D1: effective_date | E1: termination | F1: rate | G1: switch | H1: params | I1: tenor
A2: =Bloomberg_load!D2 -> sofr | B2: =Bloomberg_load!E2 -> IRS | C2: =Bloomberg_load!F2 -> OIS | D2: =Bloomberg_load!G2 -> #NAME? | E2: =Bloomberg_load!H2 -> #NAME? | F2: =Bloomberg_load!I2 -> #NAME? | G2: =IF(OR(LEFT(F2,1)="#",LEFT(E2,1)="#",LEFT(D2,1)="#"),0,1) -> #NAME? | I2: =Bloomberg_load!C2 -> 1M
A3: =Bloomberg_load!D3 -> sofr | B3: =Bloomberg_load!E3 -> IRS | C3: =Bloomberg_load!F3 -> OIS | D3: =Bloomberg_load!G3 -> #NAME? | E3: =Bloomberg_load!H3 -> #NAME? | F3: =Bloomberg_load!I3 -> #NAME? | G3: =IF(OR(LEFT(F3,1)="#",LEFT(E3,1)="#",LEFT(D3,1)="#"),0,1) -> #NAME? | I3: =Bloomberg_load!C3 -> 2M
A4: =Bloomberg_load!D4 -> sofr | B4: =Bloomberg_load!E4 -> IRS | C4: =Bloomberg_load!F4 -> OIS | D4: =Bloomberg_load!G4 -> #NAME? | E4: =Bloomberg_load!H4 -> #NAME? | F4: =Bloomberg_load!I4 -> #NAME? | G4: =IF(OR(LEFT(F4,1)="#",LEFT(E4,1)="#",LEFT(D4,1)="#"),0,1) -> #NAME? | I4: =Bloomberg_load!C4 -> 3M
A5: =Bloomberg_load!D5 -> sofr | B5: =Bloomberg_load!E5 -> IRS | C5: =Bloomberg_load!F5 -> OIS | D5: =Bloomberg_load!G5 -> #NAME? | E5: =Bloomberg_load!H5 -> #NAME? | F5: =Bloomberg_load!I5 -> #NAME? | G5: =IF(OR(LEFT(F5,1)="#",LEFT(E5,1)="#",LEFT(D5,1)="#"),0,1) -> #NAME? | I5: =Bloomberg_load!C5 -> 4M
A6: =Bloomberg_load!D6 -> sofr | B6: =Bloomberg_load!E6 -> IRS | C6: =Bloomberg_load!F6 -> OIS | D6: =Bloomberg_load!G6 -> #NAME? | E6: =Bloomberg_load!H6 -> #NAME? | F6: =Bloomberg_load!I6 -> #NAME? | G6: =IF(OR(LEFT(F6,1)="#",LEFT(E6,1)="#",LEFT(D6,1)="#"),0,1) -> #NAME? | I6: =Bloomberg_load!C6 -> 5M
A7: =Bloomberg_load!D7 -> sofr | B7: =Bloomberg_load!E7 -> IRS | C7: =Bloomberg_load!F7 -> OIS | D7: =Bloomberg_load!G7 -> #NAME? | E7: =Bloomberg_load!H7 -> #NAME? | F7: =Bloomberg_load!I7 -> #NAME? | G7: =IF(OR(LEFT(F7,1)="#",LEFT(E7,1)="#",LEFT(D7,1)="#"),0,1) -> #NAME? | I7: =Bloomberg_load!C7 -> 6M
A8: =Bloomberg_load!D8 -> sofr | B8: =Bloomberg_load!E8 -> IRS | C8: =Bloomberg_load!F8 -> OIS | D8: =Bloomberg_load!G8 -> #NAME? | E8: =Bloomberg_load!H8 -> #NAME? | F8: =Bloomberg_load!I8 -> #NAME? | G8: =IF(OR(LEFT(F8,1)="#",LEFT(E8,1)="#",LEFT(D8,1)="#"),0,1) -> #NAME? | I8: =Bloomberg_load!C8 -> 7M
A9: =Bloomberg_load!D9 -> sofr | B9: =Bloomberg_load!E9 -> IRS | C9: =Bloomberg_load!F9 -> OIS | D9: =Bloomberg_load!G9 -> #NAME? | E9: =Bloomberg_load!H9 -> #NAME? | F9: =Bloomberg_load!I9 -> #NAME? | G9: =IF(OR(LEFT(F9,1)="#",LEFT(E9,1)="#",LEFT(D9,1)="#"),0,1) -> #NAME? | I9: =Bloomberg_load!C9 -> 8M
A10: =Bloomberg_load!D10 -> sofr | B10: =Bloomberg_load!E10 -> IRS | C10: =Bloomberg_load!F10 -> OIS | D10: =Bloomberg_load!G10 -> #NAME? | E10: =Bloomberg_load!H10 -> #NAME? | F10: =Bloomberg_load!I10 -> #NAME? | G10: =IF(OR(LEFT(F10,1)="#",LEFT(E10,1)="#",LEFT(D10,1)="#"),0,1) -> #NAME? | I10: =Bloomberg_load!C10 -> 9M
A11: =Bloomberg_load!D11 -> sofr | B11: =Bloomberg_load!E11 -> IRS | C11: =Bloomberg_load!F11 -> OIS | D11: =Bloomberg_load!G11 -> #NAME? | E11: =Bloomberg_load!H11 -> #NAME? | F11: =Bloomberg_load!I11 -> #NAME? | G11: =IF(OR(LEFT(F11,1)="#",LEFT(E11,1)="#",LEFT(D11,1)="#"),0,1) -> #NAME? | I11: =Bloomberg_load!C11 -> 10M
A12: =Bloomberg_load!D12 -> sofr | B12: =Bloomberg_load!E12 -> IRS | C12: =Bloomberg_load!F12 -> OIS | D12: =Bloomberg_load!G12 -> #NAME? | E12: =Bloomberg_load!H12 -> #NAME? | F12: =Bloomberg_load!I12 -> #NAME? | G12: =IF(OR(LEFT(F12,1)="#",LEFT(E12,1)="#",LEFT(D12,1)="#"),0,1) -> #NAME? | I12: =Bloomberg_load!C12 -> 11M
A13: =Bloomberg_load!D13 -> sofr | B13: =Bloomberg_load!E13 -> IRS | C13: =Bloomberg_load!F13 -> OIS | D13: =Bloomberg_load!G13 -> #NAME? | E13: =Bloomberg_load!H13 -> #NAME? | F13: =Bloomberg_load!I13 -> #NAME? | G13: =IF(OR(LEFT(F13,1)="#",LEFT(E13,1)="#",LEFT(D13,1)="#"),0,1) -> #NAME? | I13: =Bloomberg_load!C13 -> 1Y
... A76: =Bloomberg_load!D76 -> eurusd | B76: =Bloomberg_load!E76 -> FXF | C76: =Bloomberg_load!F76 -> FXF | D76: =Bloomberg_load!G76 -> #NAME? | E76: =Bloomberg_load!H76 -> #NAME? | F76: =Bloomberg_load!I76 -> #NAME? | G76: =IF(OR(LEFT(F76,1)="#",LEFT(E76,1)="#",LEFT(D76,1)="#"),0,1) -> #NAME? | I76: =Bloomberg_load!C76 -> 5Y

Sheet Nodes
A1: curve | B1: date | C1: df
A2: {=_xlfn.vstack(_xlfn._xlws.FILTER('Node Calculation'!C4:G17,{1,0,0,0,1}),_xlfn._xlws.FILTER('Node Calculation'!C24:G36,{1,0,0,0,1}))} -> #NAME? | B2: #NAME? | C2: =IF(ISBLANK(B2),"",1) -> 1
A3: #NAME? | B3: #NAME? | C3: =IF(ISBLANK(B3),"",1) -> 1
A4: #NAME? | B4: #NAME? | C4: =IF(ISBLANK(B4),"",1) -> 1
A5: #NAME? | B5: #NAME? | C5: =IF(ISBLANK(B5),"",1) -> 1
A6: #NAME? | B6: #NAME? | C6: =IF(ISBLANK(B6),"",1) -> 1
A7: #NAME? | B7: #NAME? | C7: =IF(ISBLANK(B7),"",1) -> 1
A8: #NAME? | B8: #NAME? | C8: =IF(ISBLANK(B8),"",1) -> 1
A9: #NAME? | B9: #NAME? | C9: =IF(ISBLANK(B9),"",1) -> 1
A10: #NAME? | B10: #NAME? | C10: =IF(ISBLANK(B10),"",1) -> 1
A11: #NAME? | B11: #NAME? | C11: =IF(ISBLANK(B11),"",1) -> 1
A12: #NAME? | B12: #NAME? | C12: =IF(ISBLANK(B12),"",1) -> 1
A13: #NAME? | B13: #NAME? | C13: =IF(ISBLANK(B13),"",1) -> 1
A14: #NAME? | B14: #NAME? | C14: =IF(ISBLANK(B14),"",1) -> 1
... A28: #NAME? | B28: #NAME? | C28: =IF(ISBLANK(B28),"",1) -> 1
C29: =IF(ISBLANK(B29),"",1)
C30: =IF(ISBLANK(B30),"",1)
C31: =IF(ISBLANK(B31),"",1)
C32: =IF(ISBLANK(B32),"",1)
C33: =IF(ISBLANK(B33),"",1)
C34: =IF(ISBLANK(B34),"",1)
C35: =IF(ISBLANK(B35),"",1)
C36: =IF(ISBLANK(B36),"",1)
C37: =IF(ISBLANK(B37),"",1)
C38: =IF(ISBLANK(B38),"",1)
C39: =IF(ISBLANK(B39),"",1)
C40: =IF(ISBLANK(B40),"",1)
... C50: =IF(ISBLANK(B50),"",1)

Sheet Instruments_json
A1: =_xlfn.CONCAT(B1:J1) -> #NAME? | B1: =IF(ISBLANK(Instruments!A2),"","{"&""""&Instruments!A$1&""""&":"&""""&Instruments!A2&"""") -> {"curve":"sofr" | C1: =IF(ISBLANK(Instruments!A2),"",","&""""&Instruments!B$1&""""&":"&""""&Instruments!B2&"""") -> ,"type":"IRS" | D1: =IF(ISBLANK(Instruments!B2),"",","&""""&Instruments!C$1&""""&":"&""""&Instruments!C2&"""") -> ,"subtype":"OIS" | E1: =IF(ISBLANK(Instruments!C2),"",","&""""&Instruments!D$1&""""&":"&""""&TEXT(Instruments!D2,"yyyy-mm-dd")&"""") -> #NAME? | F1: =IF(ISBLANK(Instruments!D2),"",","&""""&Instruments!E$1&""""&":"&""""&TEXT(Instruments!E2,"yyyy-mm-dd")&"""") -> #NAME? | G1: =IF(ISBLANK(Instruments!E2),"",","&""""&Instruments!F$1&""""&":"&""""&Instruments!F2&"""") -> #NAME? | H1: =IF(ISBLANK(Instruments!F2),"",","&""""&Instruments!G$1&""""&":"&""""&Instruments!G2&"""") -> #NAME? | I1: =IF(ISBLANK(Instruments!G2),"",","&""""&Instruments!H$1&""""&":"&""""&Instruments!H2&"""") -> ,"params":"" | J1: =IF(ISBLANK(Instruments!I2),"",","&""""&Instruments!I$1&""""&":"&""""&Instruments!I2&""""&"}") -> ,"tenor":"1M"}
A2: =_xlfn.CONCAT(B2:J2) -> #NAME? | B2: =IF(ISBLANK(Instruments!A3),"","{"&""""&Instruments!A$1&""""&":"&""""&Instruments!A3&"""") -> {"curve":"sofr" | C2: =IF(ISBLANK(Instruments!A3),"",","&""""&Instruments!B$1&""""&":"&""""&Instruments!B3&"""") -> ,"type":"IRS" | D2: =IF(ISBLANK(Instruments!B3),"",","&""""&Instruments!C$1&""""&":"&""""&Instruments!C3&"""") -> ,"subtype":"OIS" | E2: =IF(ISBLANK(Instruments!C3),"",","&""""&Instruments!D$1&""""&":"&""""&TEXT(Instruments!D3,"yyyy-mm-dd")&"""") -> #NAME? | F2: =IF(ISBLANK(Instruments!D3),"",","&""""&Instruments!E$1&""""&":"&""""&TEXT(Instruments!E3,"yyyy-mm-dd")&"""") -> #NAME? | G2: =IF(ISBLANK(Instruments!E3),"",","&""""&Instruments!F$1&""""&":"&""""&Instruments!F3&"""") -> #NAME? | H2: =IF(ISBLANK(Instruments!F3),"",","&""""&Instruments!G$1&""""&":"&""""&Instruments!G3&"""") -> #NAME? | I2: =IF(ISBLANK(Instruments!G3),"",","&""""&Instruments!H$1&""""&":"&""""&Instruments!H3&"""") -> ,"params":"" | J2: =IF(ISBLANK(Instruments!I3),"",","&""""&Instruments!I$1&""""&":"&""""&Instruments!I3&""""&"}") -> ,"tenor":"2M"}
A3: =_xlfn.CONCAT(B3:J3) -> #NAME? | B3: =IF(ISBLANK(Instruments!A4),"","{"&""""&Instruments!A$1&""""&":"&""""&Instruments!A4&"""") -> {"curve":"sofr" | C3: =IF(ISBLANK(Instruments!A4),"",","&""""&Instruments!B$1&""""&":"&""""&Instruments!B4&"""") -> ,"type":"IRS" | D3: =IF(ISBLANK(Instruments!B4),"",","&""""&Instruments!C$1&""""&":"&""""&Instruments!C4&"""") -> ,"subtype":"OIS" | E3: =IF(ISBLANK(Instruments!C4),"",","&""""&Instruments!D$1&""""&":"&""""&TEXT(Instruments!D4,"yyyy-mm-dd")&"""") -> #NAME? | F3: =IF(ISBLANK(Instruments!D4),"",","&""""&Instruments!E$1&""""&":"&""""&TEXT(Instruments!E4,"yyyy-mm-dd")&"""") -> #NAME? | G3: =IF(ISBLANK(Instruments!E4),"",","&""""&Instruments!F$1&""""&":"&""""&Instruments!F4&"""") -> #NAME? | H3: =IF(ISBLANK(Instruments!F4),"",","&""""&Instruments!G$1&""""&":"&""""&Instruments!G4&"""") -> #NAME? | I3: =IF(ISBLANK(Instruments!G4),"",","&""""&Instruments!H$1&""""&":"&""""&Instruments!H4&"""") -> ,"params":"" | J3: =IF(ISBLANK(Instruments!I4),"",","&""""&Instruments!I$1&""""&":"&""""&Instruments!I4&""""&"}") -> ,"tenor":"3M"}
A4: =_xlfn.CONCAT(B4:J4) -> #NAME? | B4: =IF(ISBLANK(Instruments!A5),"","{"&""""&Instruments!A$1&""""&":"&""""&Instruments!A5&"""") -> {"curve":"sofr" | C4: =IF(ISBLANK(Instruments!A5),"",","&""""&Instruments!B$1&""""&":"&""""&Instruments!B5&"""") -> ,"type":"IRS" | D4: =IF(ISBLANK(Instruments!B5),"",","&""""&Instruments!C$1&""""&":"&""""&Instruments!C5&"""") -> ,"subtype":"OIS" | E4: =IF(ISBLANK(Instruments!C5),"",","&""""&Instruments!D$1&""""&":"&""""&TEXT(Instruments!D5,"yyyy-mm-dd")&"""") -> #NAME? | F4: =IF(ISBLANK(Instruments!D5),"",","&""""&Instruments!E$1&""""&":"&""""&TEXT(Instruments!E5,"yyyy-mm-dd")&"""") -> #NAME? | G4: =IF(ISBLANK(Instruments!E5),"",","&""""&Instruments!F$1&""""&":"&""""&Instruments!F5&"""") -> #NAME? | H4: =IF(ISBLANK(Instruments!F5),"",","&""""&Instruments!G$1&""""&":"&""""&Instruments!G5&"""") -> #NAME? | I4: =IF(ISBLANK(Instruments!G5),"",","&""""&Instruments!H$1&""""&":"&""""&Instruments!H5&"""") -> ,"params":"" | J4: =IF(ISBLANK(Instruments!I5),"",","&""""&Instruments!I$1&""""&":"&""""&Instruments!I5&""""&"}") -> ,"tenor":"4M"}
A5: =_xlfn.CONCAT(B5:J5) -> #NAME? | B5: =IF(ISBLANK(Instruments!A6),"","{"&""""&Instruments!A$1&""""&":"&""""&Instruments!A6&"""") -> {"curve":"sofr" | C5: =IF(ISBLANK(Instruments!A6),"",","&""""&Instruments!B$1&""""&":"&""""&Instruments!B6&"""") -> ,"type":"IRS" | D5: =IF(ISBLANK(Instruments!B6),"",","&""""&Instruments!C$1&""""&":"&""""&Instruments!C6&"""") -> ,"subtype":"OIS" | E5: =IF(ISBLANK(Instruments!C6),"",","&""""&Instruments!D$1&""""&":"&""""&TEXT(Instruments!D6,"yyyy-mm-dd")&"""") -> #NAME? | F5: =IF(ISBLANK(Instruments!D6),"",","&""""&Instruments!E$1&""""&":"&""""&TEXT(Instruments!E6,"yyyy-mm-dd")&"""") -> #NAME? | G5: =IF(ISBLANK(Instruments!E6),"",","&""""&Instruments!F$1&""""&":"&""""&Instruments!F6&"""") -> #NAME? | H5: =IF(ISBLANK(Instruments!F6),"",","&""""&Instruments!G$1&""""&":"&""""&Instruments!G6&"""") -> #NAME? | I5: =IF(ISBLANK(Instruments!G6),"",","&""""&Instruments!H$1&""""&":"&""""&Instruments!H6&"""") -> ,"params":"" | J5: =IF(ISBLANK(Instruments!I6),"",","&""""&Instruments!I$1&""""&":"&""""&Instruments!I6&""""&"}") -> ,"tenor":"5M"}
A6: =_xlfn.CONCAT(B6:J6) -> #NAME? | B6: =IF(ISBLANK(Instruments!A7),"","{"&""""&Instruments!A$1&""""&":"&""""&Instruments!A7&"""") -> {"curve":"sofr" | C6: =IF(ISBLANK(Instruments!A7),"",","&""""&Instruments!B$1&""""&":"&""""&Instruments!B7&"""") -> ,"type":"IRS" | D6: =IF(ISBLANK(Instruments!B7),"",","&""""&Instruments!C$1&""""&":"&""""&Instruments!C7&"""") -> ,"subtype":"OIS" | E6: =IF(ISBLANK(Instruments!C7),"",","&""""&Instruments!D$1&""""&":"&""""&TEXT(Instruments!D7,"yyyy-mm-dd")&"""") -> #NAME? | F6: =IF(ISBLANK(Instruments!D7),"",","&""""&Instruments!E$1&""""&":"&""""&TEXT(Instruments!E7,"yyyy-mm-dd")&"""") -> #NAME? | G6: =IF(ISBLANK(Instruments!E7),"",","&""""&Instruments!F$1&""""&":"&""""&Instruments!F7&"""") -> #NAME? | H6: =IF(ISBLANK(Instruments!F7),"",","&""""&Instruments!G$1&""""&":"&""""&Instruments!G7&"""") -> #NAME? | I6: =IF(ISBLANK(Instruments!G7),"",","&""""&Instruments!H$1&""""&":"&""""&Instruments!H7&"""") -> ,"params":"" | J6: =IF(ISBLANK(Instruments!I7),"",","&""""&Instruments!I$1&""""&":"&""""&Instruments!I7&""""&"}") -> ,"tenor":"6M"}
A7: =_xlfn.CONCAT(B7:J7) -> #NAME? | B7: =IF(ISBLANK(Instruments!A8),"","{"&""""&Instruments!A$1&""""&":"&""""&Instruments!A8&"""") -> {"curve":"sofr" | C7: =IF(ISBLANK(Instruments!A8),"",","&""""&Instruments!B$1&""""&":"&""""&Instruments!B8&"""") -> ,"type":"IRS" | D7: =IF(ISBLANK(Instruments!B8),"",","&""""&Instruments!C$1&""""&":"&""""&Instruments!C8&"""") -> ,"subtype":"OIS" | E7: =IF(ISBLANK(Instruments!C8),"",","&""""&Instruments!D$1&""""&":"&""""&TEXT(Instruments!D8,"yyyy-mm-dd")&"""") -> #NAME? | F7: =IF(ISBLANK(Instruments!D8),"",","&""""&Instruments!E$1&""""&":"&""""&TEXT(Instruments!E8,"yyyy-mm-dd")&"""") -> #NAME? | G7: =IF(ISBLANK(Instruments!E8),"",","&""""&Instruments!F$1&""""&":"&""""&Instruments!F8&"""") -> #NAME? | H7: =IF(ISBLANK(Instruments!F8),"",","&""""&Instruments!G$1&""""&":"&""""&Instruments!G8&"""") -> #NAME? | I7: =IF(ISBLANK(Instruments!G8),"",","&""""&Instruments!H$1&""""&":"&""""&Instruments!H8&"""") -> ,"params":"" | J7: =IF(ISBLANK(Instruments!I8),"",","&""""&Instruments!I$1&""""&":"&""""&Instruments!I8&""""&"}") -> ,"tenor":"7M"}
A8: =_xlfn.CONCAT(B8:J8) -> #NAME? | B8: =IF(ISBLANK(Instruments!A9),"","{"&""""&Instruments!A$1&""""&":"&""""&Instruments!A9&"""") -> {"curve":"sofr" | C8: =IF(ISBLANK(Instruments!A9),"",","&""""&Instruments!B$1&""""&":"&""""&Instruments!B9&"""") -> ,"type":"IRS" | D8: =IF(ISBLANK(Instruments!B9),"",","&""""&Instruments!C$1&""""&":"&""""&Instruments!C9&"""") -> ,"subtype":"OIS" | E8: =IF(ISBLANK(Instruments!C9),"",","&""""&Instruments!D$1&""""&":"&""""&TEXT(Instruments!D9,"yyyy-mm-dd")&"""") -> #NAME? | F8: =IF(ISBLANK(Instruments!D9),"",","&""""&Instruments!E$1&""""&":"&""""&TEXT(Instruments!E9,"yyyy-mm-dd")&"""") -> #NAME? | G8: =IF(ISBLANK(Instruments!E9),"",","&""""&Instruments!F$1&""""&":"&""""&Instruments!F9&"""") -> #NAME? | H8: =IF(ISBLANK(Instruments!F9),"",","&""""&Instruments!G$1&""""&":"&""""&Instruments!G9&"""") -> #NAME? | I8: =IF(ISBLANK(Instruments!G9),"",","&""""&Instruments!H$1&""""&":"&""""&Instruments!H9&"""") -> ,"params":"" | J8: =IF(ISBLANK(Instruments!I9),"",","&""""&Instruments!I$1&""""&":"&""""&Instruments!I9&""""&"}") -> ,"tenor":"8M"}
A9: =_xlfn.CONCAT(B9:J9) -> #NAME? | B9: =IF(ISBLANK(Instruments!A10),"","{"&""""&Instruments!A$1&""""&":"&""""&Instruments!A10&"""") -> {"curve":"sofr" | C9: =IF(ISBLANK(Instruments!A10),"",","&""""&Instruments!B$1&""""&":"&""""&Instruments!B10&"""") -> ,"type":"IRS" | D9: =IF(ISBLANK(Instruments!B10),"",","&""""&Instruments!C$1&""""&":"&""""&Instruments!C10&"""") -> ,"subtype":"OIS" | E9: =IF(ISBLANK(Instruments!C10),"",","&""""&Instruments!D$1&""""&":"&""""&TEXT(Instruments!D10,"yyyy-mm-dd")&"""") -> #NAME? | F9: =IF(ISBLANK(Instruments!D10),"",","&""""&Instruments!E$1&""""&":"&""""&TEXT(Instruments!E10,"yyyy-mm-dd")&"""") -> #NAME? | G9: =IF(ISBLANK(Instruments!E10),"",","&""""&Instruments!F$1&""""&":"&""""&Instruments!F10&"""") -> #NAME? | H9: =IF(ISBLANK(Instruments!F10),"",","&""""&Instruments!G$1&""""&":"&""""&Instruments!G10&"""") -> #NAME? | I9: =IF(ISBLANK(Instruments!G10),"",","&""""&Instruments!H$1&""""&":"&""""&Instruments!H10&"""") -> ,"params":"" | J9: =IF(ISBLANK(Instruments!I10),"",","&""""&Instruments!I$1&""""&":"&""""&Instruments!I10&""""&"}") -> ,"tenor":"9M"}
A10: =_xlfn.CONCAT(B10:J10) -> #NAME? | B10: =IF(ISBLANK(Instruments!A11),"","{"&""""&Instruments!A$1&""""&":"&""""&Instruments!A11&"""") -> {"curve":"sofr" | C10: =IF(ISBLANK(Instruments!A11),"",","&""""&Instruments!B$1&""""&":"&""""&Instruments!B11&"""") -> ,"type":"IRS" | D10: =IF(ISBLANK(Instruments!B11),"",","&""""&Instruments!C$1&""""&":"&""""&Instruments!C11&"""") -> ,"subtype":"OIS" | E10: =IF(ISBLANK(Instruments!C11),"",","&""""&Instruments!D$1&""""&":"&""""&TEXT(Instruments!D11,"yyyy-mm-dd")&"""") -> #NAME? | F10: =IF(ISBLANK(Instruments!D11),"",","&""""&Instruments!E$1&""""&":"&""""&TEXT(Instruments!E11,"yyyy-mm-dd")&"""") -> #NAME? | G10: =IF(ISBLANK(Instruments!E11),"",","&""""&Instruments!F$1&""""&":"&""""&Instruments!F11&"""") -> #NAME? | H10: =IF(ISBLANK(Instruments!F11),"",","&""""&Instruments!G$1&""""&":"&""""&Instruments!G11&"""") -> #NAME? | I10: =IF(ISBLANK(Instruments!G11),"",","&""""&Instruments!H$1&""""&":"&""""&Instruments!H11&"""") -> ,"params":"" | J10: =IF(ISBLANK(Instruments!I11),"",","&""""&Instruments!I$1&""""&":"&""""&Instruments!I11&""""&"}") -> ,"tenor":"10M"}
A11: =_xlfn.CONCAT(B11:J11) -> #NAME? | B11: =IF(ISBLANK(Instruments!A12),"","{"&""""&Instruments!A$1&""""&":"&""""&Instruments!A12&"""") -> {"curve":"sofr" | C11: =IF(ISBLANK(Instruments!A12),"",","&""""&Instruments!B$1&""""&":"&""""&Instruments!B12&"""") -> ,"type":"IRS" | D11: =IF(ISBLANK(Instruments!B12),"",","&""""&Instruments!C$1&""""&":"&""""&Instruments!C12&"""") -> ,"subtype":"OIS" | E11: =IF(ISBLANK(Instruments!C12),"",","&""""&Instruments!D$1&""""&":"&""""&TEXT(Instruments!D12,"yyyy-mm-dd")&"""") -> #NAME? | F11: =IF(ISBLANK(Instruments!D12),"",","&""""&Instruments!E$1&""""&":"&""""&TEXT(Instruments!E12,"yyyy-mm-dd")&"""") -> #NAME? | G11: =IF(ISBLANK(Instruments!E12),"",","&""""&Instruments!F$1&""""&":"&""""&Instruments!F12&"""") -> #NAME? | H11: =IF(ISBLANK(Instruments!F12),"",","&""""&Instruments!G$1&""""&":"&""""&Instruments!G12&"""") -> #NAME? | I11: =IF(ISBLANK(Instruments!G12),"",","&""""&Instruments!H$1&""""&":"&""""&Instruments!H12&"""") -> ,"params":"" | J11: =IF(ISBLANK(Instruments!I12),"",","&""""&Instruments!I$1&""""&":"&""""&Instruments!I12&""""&"}") -> ,"tenor":"11M"}
A12: =_xlfn.CONCAT(B12:J12) -> #NAME? | B12: =IF(ISBLANK(Instruments!A13),"","{"&""""&Instruments!A$1&""""&":"&""""&Instruments!A13&"""") -> {"curve":"sofr" | C12: =IF(ISBLANK(Instruments!A13),"",","&""""&Instruments!B$1&""""&":"&""""&Instruments!B13&"""") -> ,"type":"IRS" | D12: =IF(ISBLANK(Instruments!B13),"",","&""""&Instruments!C$1&""""&":"&""""&Instruments!C13&"""") -> ,"subtype":"OIS" | E12: =IF(ISBLANK(Instruments!C13),"",","&""""&Instruments!D$1&""""&":"&""""&TEXT(Instruments!D13,"yyyy-mm-dd")&"""") -> #NAME? | F12: =IF(ISBLANK(Instruments!D13),"",","&""""&Instruments!E$1&""""&":"&""""&TEXT(Instruments!E13,"yyyy-mm-dd")&"""") -> #NAME? | G12: =IF(ISBLANK(Instruments!E13),"",","&""""&Instruments!F$1&""""&":"&""""&Instruments!F13&"""") -> #NAME? | H12: =IF(ISBLANK(Instruments!F13),"",","&""""&Instruments!G$1&""""&":"&""""&Instruments!G13&"""") -> #NAME? | I12: =IF(ISBLANK(Instruments!G13),"",","&""""&Instruments!H$1&""""&":"&""""&Instruments!H13&"""") -> ,"params":"" | J12: =IF(ISBLANK(Instruments!I13),"",","&""""&Instruments!I$1&""""&":"&""""&Instruments!I13&""""&"}") -> ,"tenor":"1Y"}
... A149: =_xlfn.CONCAT(B149:J149) | B149: =IF(ISBLANK(Instruments!A150),"","{"&""""&Instruments!A$1&""""&":"&""""&Instruments!A150&"""") | C149: =IF(ISBLANK(Instruments!A150),"",","&""""&Instruments!B$1&""""&":"&""""&Instruments!B150&"""") | D149: =IF(ISBLANK(Instruments!B150),"",","&""""&Instruments!C$1&""""&":"&""""&Instruments!C150&"""") | E149: =IF(ISBLANK(Instruments!C150),"",","&""""&Instruments!D$1&""""&":"&""""&TEXT(Instruments!D150,"yyyy-mm-dd")&"""") | F149: =IF(ISBLANK(Instruments!D150),"",","&""""&Instruments!E$1&""""&":"&""""&TEXT(Instruments!E150,"yyyy-mm-dd")&"""") | G149: =IF(ISBLANK(Instruments!E150),"",","&""""&Instruments!F$1&""""&":"&""""&Instruments!F150&"""") | H149: =IF(ISBLANK(Instruments!F150),"",","&""""&Instruments!G$1&""""&":"&""""&Instruments!G150&"""") | I149: =IF(ISBLANK(Instruments!G150),"",","&""""&Instruments!H$1&""""&":"&""""&Instruments!H150&"""") | J149: =IF(ISBLANK(Instruments!I150),"",","&""""&Instruments!I$1&""""&":"&""""&Instruments!I150&""""&"}")

Sheet Nodes_json
A1: =_xlfn.CONCAT(B1:D1) -> #NAME? | B1: =IF(ISBLANK(Nodes!A2),"","{"&""""&Nodes!A$1&""""&":"&""""&Nodes!A2&"""") -> #NAME? | C1: =IF(ISBLANK(Nodes!B2),"",","&""""&Nodes!B$1&""""&":"&""""&TEXT(Nodes!B2,"yyyy-mm-dd")&"""") -> #NAME? | D1: =IF(Nodes!C2="","",","&""""&Nodes!C$1&""""&":"&""""&Nodes!C2&""""&"}") -> ,"df":"1"}
A2: =_xlfn.CONCAT(B2:D2) -> #NAME? | B2: =IF(ISBLANK(Nodes!A3),"","{"&""""&Nodes!A$1&""""&":"&""""&Nodes!A3&"""") -> #NAME? | C2: =IF(ISBLANK(Nodes!B3),"",","&""""&Nodes!B$1&""""&":"&""""&TEXT(Nodes!B3,"yyyy-mm-dd")&"""") -> #NAME? | D2: =IF(Nodes!C3="","",","&""""&Nodes!C$1&""""&":"&""""&Nodes!C3&""""&"}") -> ,"df":"1"}
A3: =_xlfn.CONCAT(B3:D3) -> #NAME? | B3: =IF(ISBLANK(Nodes!A4),"","{"&""""&Nodes!A$1&""""&":"&""""&Nodes!A4&"""") -> #NAME? | C3: =IF(ISBLANK(Nodes!B4),"",","&""""&Nodes!B$1&""""&":"&""""&TEXT(Nodes!B4,"yyyy-mm-dd")&"""") -> #NAME? | D3: =IF(Nodes!C4="","",","&""""&Nodes!C$1&""""&":"&""""&Nodes!C4&""""&"}") -> ,"df":"1"}
A4: =_xlfn.CONCAT(B4:D4) -> #NAME? | B4: =IF(ISBLANK(Nodes!A5),"","{"&""""&Nodes!A$1&""""&":"&""""&Nodes!A5&"""") -> #NAME? | C4: =IF(ISBLANK(Nodes!B5),"",","&""""&Nodes!B$1&""""&":"&""""&TEXT(Nodes!B5,"yyyy-mm-dd")&"""") -> #NAME? | D4: =IF(Nodes!C5="","",","&""""&Nodes!C$1&""""&":"&""""&Nodes!C5&""""&"}") -> ,"df":"1"}
A5: =_xlfn.CONCAT(B5:D5) -> #NAME? | B5: =IF(ISBLANK(Nodes!A6),"","{"&""""&Nodes!A$1&""""&":"&""""&Nodes!A6&"""") -> #NAME? | C5: =IF(ISBLANK(Nodes!B6),"",","&""""&Nodes!B$1&""""&":"&""""&TEXT(Nodes!B6,"yyyy-mm-dd")&"""") -> #NAME? | D5: =IF(Nodes!C6="","",","&""""&Nodes!C$1&""""&":"&""""&Nodes!C6&""""&"}") -> ,"df":"1"}
A6: =_xlfn.CONCAT(B6:D6) -> #NAME? | B6: =IF(ISBLANK(Nodes!A7),"","{"&""""&Nodes!A$1&""""&":"&""""&Nodes!A7&"""") -> #NAME? | C6: =IF(ISBLANK(Nodes!B7),"",","&""""&Nodes!B$1&""""&":"&""""&TEXT(Nodes!B7,"yyyy-mm-dd")&"""") -> #NAME? | D6: =IF(Nodes!C7="","",","&""""&Nodes!C$1&""""&":"&""""&Nodes!C7&""""&"}") -> ,"df":"1"}
A7: =_xlfn.CONCAT(B7:D7) -> #NAME? | B7: =IF(ISBLANK(Nodes!A8),"","{"&""""&Nodes!A$1&""""&":"&""""&Nodes!A8&"""") -> #NAME? | C7: =IF(ISBLANK(Nodes!B8),"",","&""""&Nodes!B$1&""""&":"&""""&TEXT(Nodes!B8,"yyyy-mm-dd")&"""") -> #NAME? | D7: =IF(Nodes!C8="","",","&""""&Nodes!C$1&""""&":"&""""&Nodes!C8&""""&"}") -> ,"df":"1"}
A8: =_xlfn.CONCAT(B8:D8) -> #NAME? | B8: =IF(ISBLANK(Nodes!A9),"","{"&""""&Nodes!A$1&""""&":"&""""&Nodes!A9&"""") -> #NAME? | C8: =IF(ISBLANK(Nodes!B9),"",","&""""&Nodes!B$1&""""&":"&""""&TEXT(Nodes!B9,"yyyy-mm-dd")&"""") -> #NAME? | D8: =IF(Nodes!C9="","",","&""""&Nodes!C$1&""""&":"&""""&Nodes!C9&""""&"}") -> ,"df":"1"}
A9: =_xlfn.CONCAT(B9:D9) -> #NAME? | B9: =IF(ISBLANK(Nodes!A10),"","{"&""""&Nodes!A$1&""""&":"&""""&Nodes!A10&"""") -> #NAME? | C9: =IF(ISBLANK(Nodes!B10),"",","&""""&Nodes!B$1&""""&":"&""""&TEXT(Nodes!B10,"yyyy-mm-dd")&"""") -> #NAME? | D9: =IF(Nodes!C10="","",","&""""&Nodes!C$1&""""&":"&""""&Nodes!C10&""""&"}") -> ,"df":"1"}
A10: =_xlfn.CONCAT(B10:D10) -> #NAME? | B10: =IF(ISBLANK(Nodes!A11),"","{"&""""&Nodes!A$1&""""&":"&""""&Nodes!A11&"""") -> #NAME? | C10: =IF(ISBLANK(Nodes!B11),"",","&""""&Nodes!B$1&""""&":"&""""&TEXT(Nodes!B11,"yyyy-mm-dd")&"""") -> #NAME? | D10: =IF(Nodes!C11="","",","&""""&Nodes!C$1&""""&":"&""""&Nodes!C11&""""&"}") -> ,"df":"1"}
A11: =_xlfn.CONCAT(B11:D11) -> #NAME? | B11: =IF(ISBLANK(Nodes!A12),"","{"&""""&Nodes!A$1&""""&":"&""""&Nodes!A12&"""") -> #NAME? | C11: =IF(ISBLANK(Nodes!B12),"",","&""""&Nodes!B$1&""""&":"&""""&TEXT(Nodes!B12,"yyyy-mm-dd")&"""") -> #NAME? | D11: =IF(Nodes!C12="","",","&""""&Nodes!C$1&""""&":"&""""&Nodes!C12&""""&"}") -> ,"df":"1"}
A12: =_xlfn.CONCAT(B12:D12) -> #NAME? | B12: =IF(ISBLANK(Nodes!A13),"","{"&""""&Nodes!A$1&""""&":"&""""&Nodes!A13&"""") -> #NAME? | C12: =IF(ISBLANK(Nodes!B13),"",","&""""&Nodes!B$1&""""&":"&""""&TEXT(Nodes!B13,"yyyy-mm-dd")&"""") -> #NAME? | D12: =IF(Nodes!C13="","",","&""""&Nodes!C$1&""""&":"&""""&Nodes!C13&""""&"}") -> ,"df":"1"}
... A150: =_xlfn.CONCAT(B150:D150) | B150: =IF(ISBLANK(Nodes!A151),"","{"&""""&Nodes!A$1&""""&":"&""""&Nodes!A151&"""") | C150: =IF(ISBLANK(Nodes!B151),"",","&""""&Nodes!B$1&""""&":"&""""&TEXT(Nodes!B151,"yyyy-mm-dd")&"""") | D150: =IF(Nodes!C151="","",","&""""&Nodes!C$1&""""&":"&""""&Nodes!C151&""""&"}")

Sheet Node Calculation
A1: SOFR
A2: Ticker | B2: Tenor | C2: Curve | G2: Node | J2: {=_xlfn._xlws.FILTER(C4:G36,OR(C4:C36="sofr",C4:C36="estr"))} -> #NAME?
A3: Final CB | E3: {=MAX(_xlfn._xlws.FILTER(Bloomberg_load!$H$2:$H$76,LEFT(Bloomberg_load!$C$2:$C$76,3)="FED"))} -> #NAME?
A4: Today | C4: sofr | G4: =TODAY() -> 45782
A5: {=_xlfn.vstack(_xlfn._xlws.FILTER(Bloomberg_load!B18:H25,LEFT(Bloomberg_load!H18:H25,1)<>"#"),_xlfn._xlws.FILTER(Bloomberg_load!B2:H17,Bloomberg_load!H2:H17>'Node Calculation'!E3))} -> #NAME? | B5: #NAME? | C5: #NAME? | D5: #NAME? | E5: #NAME? | F5: #NAME? | G5: #NAME?
A6: #NAME? | B6: #NAME? | C6: #NAME? | D6: #NAME? | E6: #NAME? | F6: #NAME? | G6: #NAME?
A7: #NAME? | B7: #NAME? | C7: #NAME? | D7: #NAME? | E7: #NAME? | F7: #NAME? | G7: #NAME?
A8: #NAME? | B8: #NAME? | C8: #NAME? | D8: #NAME? | E8: #NAME? | F8: #NAME? | G8: #NAME?
A9: #NAME? | B9: #NAME? | C9: #NAME? | D9: #NAME? | E9: #NAME? | F9: #NAME? | G9: #NAME?
A10: #NAME? | B10: #NAME? | C10: #NAME? | D10: #NAME? | E10: #NAME? | F10: #NAME? | G10: #NAME?
A11: #NAME? | B11: #NAME? | C11: #NAME? | D11: #NAME? | E11: #NAME? | F11: #NAME? | G11: #NAME?
A12: #NAME? | B12: #NAME? | C12: #NAME? | D12: #NAME? | E12: #NAME? | F12: #NAME? | G12: #NAME?
A13: #NAME? | B13: #NAME? | C13: #NAME? | D13: #NAME? | E13: #NAME? | F13: #NAME? | G13: #NAME?
A14: #NAME? | B14: #NAME? | C14: #NAME? | D14: #NAME? | E14: #NAME? | F14: #NAME? | G14: #NAME?
A15: #NAME? | B15: #NAME? | C15: #NAME? | D15: #NAME? | E15: #NAME? | F15: #NAME? | G15: #NAME?
A16: #NAME? | B16: #NAME? | C16: #NAME? | D16: #NAME? | E16: #NAME? | F16: #NAME? | G16: #NAME?
A17: #NAME? | B17: #NAME? | C17: #NAME? | D17: #NAME? | E17: #NAME? | F17: #NAME? | G17: #NAME?
A21: ESTR
A22: Ticker | B22: Tenor | C22: Curve | G22: Node
A23: Final CB | E23: {=MAX(_xlfn._xlws.FILTER(Bloomberg_load!$H$2:$H$76,LEFT(Bloomberg_load!$C$2:$C$76,3)="ECB"))} -> #NAME?
A24: Today | C24: estr | G24: =TODAY() -> 45782
A25: {=_xlfn.vstack(_xlfn._xlws.FILTER(Bloomberg_load!B43:H50,LEFT(Bloomberg_load!H43:H50,1)<>"#"),_xlfn._xlws.FILTER(Bloomberg_load!B26:H41,Bloomberg_load!H26:H41>'Node Calculation'!E23))} -> #NAME? | B25: #NAME? | C25: #NAME? | D25: #NAME? | E25: #NAME? | F25: #NAME? | G25: #NAME?
A26: #NAME? | B26: #NAME? | C26: #NAME? | D26: #NAME? | E26: #NAME? | F26: #NAME? | G26: #NAME?
A27: #NAME? | B27: #NAME? | C27: #NAME? | D27: #NAME? | E27: #NAME? | F27: #NAME? | G27: #NAME?
A28: #NAME? | B28: #NAME? | C28: #NAME? | D28: #NAME? | E28: #NAME? | F28: #NAME? | G28: #NAME?
A29: #NAME? | B29: #NAME? | C29: #NAME? | D29: #NAME? | E29: #NAME? | F29: #NAME? | G29: #NAME?
A30: #NAME? | B30: #NAME? | C30: #NAME? | D30: #NAME? | E30: #NAME? | F30: #NAME? | G30: #NAME?
A31: #NAME? | B31: #NAME? | C31: #NAME? | D31: #NAME? | E31: #NAME? | F31: #NAME? | G31: #NAME?
A32: #NAME? | B32: #NAME? | C32: #NAME? | D32: #NAME? | E32: #NAME? | F32: #NAME? | G32: #NAME?
A33: #NAME? | B33: #NAME? | C33: #NAME? | D33: #NAME? | E33: #NAME? | F33: #NAME? | G33: #NAME?
A34: #NAME? | B34: #NAME? | C34: #NAME? | D34: #NAME? | E34: #NAME? | F34: #NAME? | G34: #NAME?
A35: #NAME? | B35: #NAME? | C35: #NAME? | D35: #NAME? | E35: #NAME? | F35: #NAME? | G35: #NAME?
A36: #NAME? | B36: #NAME? | C36: #NAME? | D36: #NAME? | E36: #NAME? | F36: #NAME? | G36: #NAME?

Sheet Bloomberg_load
A1: Label | B1: Ticker | D1: Curve | E1: Type | F1: Subtype | G1: SETTLE_DT | H1: MATURITY | I1: LAST_PRICE
A2: A | B2: ="USSO"&A2 -> USSOA | C2: 1M | D2: sofr | E2: IRS | F2: OIS | G2: {=DATEVALUE(_xll.bdp($B2&" Curncy",G$1))} -> #NAME? | H2: {=DATEVALUE(_xll.bdp($B2&" Curncy",H$1))} -> #NAME? | I2: {=_xll.bdp($B2&" Curncy",I$1)} -> #NAME?
A3: B | B3: ="USSO"&A3 -> USSOB | C3: 2M | D3: sofr | E3: IRS | F3: OIS | G3: {=DATEVALUE(_xll.bdp($B3&" Curncy",G$1))} -> #NAME? | H3: {=DATEVALUE(_xll.bdp($B3&" Curncy",H$1))} -> #NAME? | I3: {=_xll.bdp($B3&" Curncy",I$1)} -> #NAME?
A4: C | B4: ="USSO"&A4 -> USSOC | C4: 3M | D4: sofr | E4: IRS | F4: OIS | G4: {=DATEVALUE(_xll.bdp($B4&" Curncy",G$1))} -> #NAME? | H4: {=DATEVALUE(_xll.bdp($B4&" Curncy",H$1))} -> #NAME? | I4: {=_xll.bdp($B4&" Curncy",I$1)} -> #NAME?
A5: D | B5: ="USSO"&A5 -> USSOD | C5: 4M | D5: sofr | E5: IRS | F5: OIS | G5: {=DATEVALUE(_xll.bdp($B5&" Curncy",G$1))} -> #NAME? | H5: {=DATEVALUE(_xll.bdp($B5&" Curncy",H$1))} -> #NAME? | I5: {=_xll.bdp($B5&" Curncy",I$1)} -> #NAME?
A6: E | B6: ="USSO"&A6 -> USSOE | C6: 5M | D6: sofr | E6: IRS | F6: OIS | G6: {=DATEVALUE(_xll.bdp($B6&" Curncy",G$1))} -> #NAME? | H6: {=DATEVALUE(_xll.bdp($B6&" Curncy",H$1))} -> #NAME? | I6: {=_xll.bdp($B6&" Curncy",I$1)} -> #NAME?
A7: F | B7: ="USSO"&A7 -> USSOF | C7: 6M | D7: sofr | E7: IRS | F7: OIS | G7: {=DATEVALUE(_xll.bdp($B7&" Curncy",G$1))} -> #NAME? | H7: {=DATEVALUE(_xll.bdp($B7&" Curncy",H$1))} -> #NAME? | I7: {=_xll.bdp($B7&" Curncy",I$1)} -> #NAME?
A8: G | B8: ="USSO"&A8 -> USSOG | C8: 7M | D8: sofr | E8: IRS | F8: OIS | G8: {=DATEVALUE(_xll.bdp($B8&" Curncy",G$1))} -> #NAME? | H8: {=DATEVALUE(_xll.bdp($B8&" Curncy",H$1))} -> #NAME? | I8: {=_xll.bdp($B8&" Curncy",I$1)} -> #NAME?
A9: H | B9: ="USSO"&A9 -> USSOH | C9: 8M | D9: sofr | E9: IRS | F9: OIS | G9: {=DATEVALUE(_xll.bdp($B9&" Curncy",G$1))} -> #NAME? | H9: {=DATEVALUE(_xll.bdp($B9&" Curncy",H$1))} -> #NAME? | I9: {=_xll.bdp($B9&" Curncy",I$1)} -> #NAME?
A10: I | B10: ="USSO"&A10 -> USSOI | C10: 9M | D10: sofr | E10: IRS | F10: OIS | G10: {=DATEVALUE(_xll.bdp($B10&" Curncy",G$1))} -> #NAME? | H10: {=DATEVALUE(_xll.bdp($B10&" Curncy",H$1))} -> #NAME? | I10: {=_xll.bdp($B10&" Curncy",I$1)} -> #NAME?
A11: J | B11: ="USSO"&A11 -> USSOJ | C11: 10M | D11: sofr | E11: IRS | F11: OIS | G11: {=DATEVALUE(_xll.bdp($B11&" Curncy",G$1))} -> #NAME? | H11: {=DATEVALUE(_xll.bdp($B11&" Curncy",H$1))} -> #NAME? | I11: {=_xll.bdp($B11&" Curncy",I$1)} -> #NAME?
A12: K | B12: ="USSO"&A12 -> USSOK | C12: 11M | D12: sofr | E12: IRS | F12: OIS | G12: {=DATEVALUE(_xll.bdp($B12&" Curncy",G$1))} -> #NAME? | H12: {=DATEVALUE(_xll.bdp($B12&" Curncy",H$1))} -> #NAME? | I12: {=_xll.bdp($B12&" Curncy",I$1)} -> #NAME?
A13: 1 | B13: ="USSO"&A13 -> USSO1 | C13: 1Y | D13: sofr | E13: IRS | F13: OIS | G13: {=DATEVALUE(_xll.bdp($B13&" Curncy",G$1))} -> #NAME? | H13: {=DATEVALUE(_xll.bdp($B13&" Curncy",H$1))} -> #NAME? | I13: {=_xll.bdp($B13&" Curncy",I$1)} -> #NAME?
A14: 2 | B14: ="USSO"&A14 -> USSO2 | C14: 2Y | D14: sofr | E14: IRS | F14: OIS | G14: {=DATEVALUE(_xll.bdp($B14&" Curncy",G$1))} -> #NAME? | H14: {=DATEVALUE(_xll.bdp($B14&" Curncy",H$1))} -> #NAME? | I14: {=_xll.bdp($B14&" Curncy",I$1)} -> #NAME?
A15: 3 | B15: ="USSO"&A15 -> USSO3 | C15: 3Y | D15: sofr | E15: IRS | F15: OIS | G15: {=DATEVALUE(_xll.bdp($B15&" Curncy",G$1))} -> #NAME? | H15: {=DATEVALUE(_xll.bdp($B15&" Curncy",H$1))} -> #NAME? | I15: {=_xll.bdp($B15&" Curncy",I$1)} -> #NAME?
A16: 4 | B16: ="USSO"&A16 -> USSO4 | C16: 4Y | D16: sofr | E16: IRS | F16: OIS | G16: {=DATEVALUE(_xll.bdp($B16&" Curncy",G$1))} -> #NAME? | H16: {=DATEVALUE(_xll.bdp($B16&" Curncy",H$1))} -> #NAME? | I16: {=_xll.bdp($B16&" Curncy",I$1)} -> #NAME?
A17: 5 | B17: ="USSO"&A17 -> USSO5 | C17: 5Y | D17: sofr | E17: IRS | F17: OIS | G17: {=DATEVALUE(_xll.bdp($B17&" Curncy",G$1))} -> #NAME? | H17: {=DATEVALUE(_xll.bdp($B17&" Curncy",H$1))} -> #NAME? | I17: {=_xll.bdp($B17&" Curncy",I$1)} -> #NAME?
A18: 1 | B18: ="USSOFED"&A18 -> USSOFED1 | C18: =RIGHT(B18,4) -> FED1 | D18: sofr | E18: IRS | F18: CBOIS | G18: {=DATEVALUE(_xll.bdp($B18&" Curncy",G$1))} -> #NAME? | H18: {=DATEVALUE(_xll.bdp($B18&" Curncy",H$1))} -> #NAME? | I18: {=_xll.bdp($B18&" Curncy",I$1)} -> #NAME?
A19: 2 | B19: ="USSOFED"&A19 -> USSOFED2 | C19: =RIGHT(B19,4) -> FED2 | D19: sofr | E19: IRS | F19: CBOIS | G19: {=DATEVALUE(_xll.bdp($B19&" Curncy",G$1))} -> #NAME? | H19: {=DATEVALUE(_xll.bdp($B19&" Curncy",H$1))} -> #NAME? | I19: {=_xll.bdp($B19&" Curncy",I$1)} -> #NAME?
A20: 3 | B20: ="USSOFED"&A20 -> USSOFED3 | C20: =RIGHT(B20,4) -> FED3 | D20: sofr | E20: IRS | F20: CBOIS | G20: {=DATEVALUE(_xll.bdp($B20&" Curncy",G$1))} -> #NAME? | H20: {=DATEVALUE(_xll.bdp($B20&" Curncy",H$1))} -> #NAME? | I20: {=_xll.bdp($B20&" Curncy",I$1)} -> #NAME?
A21: 4 | B21: ="USSOFED"&A21 -> USSOFED4 | C21: =RIGHT(B21,4) -> FED4 | D21: sofr | E21: IRS | F21: CBOIS | G21: {=DATEVALUE(_xll.bdp($B21&" Curncy",G$1))} -> #NAME? | H21: {=DATEVALUE(_xll.bdp($B21&" Curncy",H$1))} -> #NAME? | I21: {=_xll.bdp($B21&" Curncy",I$1)} -> #NAME?
A22: 5 | B22: ="USSOFED"&A22 -> USSOFED5 | C22: =RIGHT(B22,4) -> FED5 | D22: sofr | E22: IRS | F22: CBOIS | G22: {=DATEVALUE(_xll.bdp($B22&" Curncy",G$1))} -> #NAME? | H22: {=DATEVALUE(_xll.bdp($B22&" Curncy",H$1))} -> #NAME? | I22: {=_xll.bdp($B22&" Curncy",I$1)} -> #NAME?
A23: 6 | B23: ="USSOFED"&A23 -> USSOFED6 | C23: =RIGHT(B23,4) -> FED6 | D23: sofr | E23: IRS | F23: CBOIS | G23: {=DATEVALUE(_xll.bdp($B23&" Curncy",G$1))} -> #NAME? | H23: {=DATEVALUE(_xll.bdp($B23&" Curncy",H$1))} -> #NAME? | I23: {=_xll.bdp($B23&" Curncy",I$1)} -> #NAME?
A24: 7 | B24: ="USSOFED"&A24 -> USSOFED7 | C24: =RIGHT(B24,4) -> FED7 | D24: sofr | E24: IRS | F24: CBOIS | G24: {=DATEVALUE(_xll.bdp($B24&" Curncy",G$1))} -> #NAME? | H24: {=DATEVALUE(_xll.bdp($B24&" Curncy",H$1))} -> #NAME? | I24: {=_xll.bdp($B24&" Curncy",I$1)} -> #NAME?
A25: 8 | B25: ="USSOFED"&A25 -> USSOFED8 | C25: =RIGHT(B25,4) -> FED8 | D25: sofr | E25: IRS | F25: CBOIS | G25: {=DATEVALUE(_xll.bdp($B25&" Curncy",G$1))} -> #NAME? | H25: {=DATEVALUE(_xll.bdp($B25&" Curncy",H$1))} -> #NAME? | I25: {=_xll.bdp($B25&" Curncy",I$1)} -> #NAME?
A26: A | B26: ="EESWE"&A26 -> EESWEA | C26: 1M | D26: estr | E26: IRS | F26: OIS | G26: {=DATEVALUE(_xll.bdp($B26&" Curncy",G$1))} -> #NAME? | H26: {=DATEVALUE(_xll.bdp($B26&" Curncy",H$1))} -> #NAME? | I26: {=_xll.bdp($B26&" Curncy",I$1)} -> #NAME?
A27: B | B27: ="EESWE"&A27 -> EESWEB | C27: 2M | D27: estr | E27: IRS | F27: OIS | G27: {=DATEVALUE(_xll.bdp($B27&" Curncy",G$1))} -> #NAME? | H27: {=DATEVALUE(_xll.bdp($B27&" Curncy",H$1))} -> #NAME? | I27: {=_xll.bdp($B27&" Curncy",I$1)} -> #NAME?
A28: C | B28: ="EESWE"&A28 -> EESWEC | C28: 3M | D28: estr | E28: IRS | F28: OIS | G28: {=DATEVALUE(_xll.bdp($B28&" Curncy",G$1))} -> #NAME? | H28: {=DATEVALUE(_xll.bdp($B28&" Curncy",H$1))} -> #NAME? | I28: {=_xll.bdp($B28&" Curncy",I$1)} -> #NAME?
A29: D | B29: ="EESWE"&A29 -> EESWED | C29: 4M | D29: estr | E29: IRS | F29: OIS | G29: {=DATEVALUE(_xll.bdp($B29&" Curncy",G$1))} -> #NAME? | H29: {=DATEVALUE(_xll.bdp($B29&" Curncy",H$1))} -> #NAME? | I29: {=_xll.bdp($B29&" Curncy",I$1)} -> #NAME?
A30: E | B30: ="EESWE"&A30 -> EESWEE | C30: 5M | D30: estr | E30: IRS | F30: OIS | G30: {=DATEVALUE(_xll.bdp($B30&" Curncy",G$1))} -> #NAME? | H30: {=DATEVALUE(_xll.bdp($B30&" Curncy",H$1))} -> #NAME? | I30: {=_xll.bdp($B30&" Curncy",I$1)} -> #NAME?
A31: F | B31: ="EESWE"&A31 -> EESWEF | C31: 6M | D31: estr | E31: IRS | F31: OIS | G31: {=DATEVALUE(_xll.bdp($B31&" Curncy",G$1))} -> #NAME? | H31: {=DATEVALUE(_xll.bdp($B31&" Curncy",H$1))} -> #NAME? | I31: {=_xll.bdp($B31&" Curncy",I$1)} -> #NAME?
A32: G | B32: ="EESWE"&A32 -> EESWEG | C32: 7M | D32: estr | E32: IRS | F32: OIS | G32: {=DATEVALUE(_xll.bdp($B32&" Curncy",G$1))} -> #NAME? | H32: {=DATEVALUE(_xll.bdp($B32&" Curncy",H$1))} -> #NAME? | I32: {=_xll.bdp($B32&" Curncy",I$1)} -> #NAME?
A33: H | B33: ="EESWE"&A33 -> EESWEH | C33: 8M | D33: estr | E33: IRS | F33: OIS | G33: {=DATEVALUE(_xll.bdp($B33&" Curncy",G$1))} -> #NAME? | H33: {=DATEVALUE(_xll.bdp($B33&" Curncy",H$1))} -> #NAME? | I33: {=_xll.bdp($B33&" Curncy",I$1)} -> #NAME?
A34: I | B34: ="EESWE"&A34 -> EESWEI | C34: 9M | D34: estr | E34: IRS | F34: OIS | G34: {=DATEVALUE(_xll.bdp($B34&" Curncy",G$1))} -> #NAME? | H34: {=DATEVALUE(_xll.bdp($B34&" Curncy",H$1))} -> #NAME? | I34: {=_xll.bdp($B34&" Curncy",I$1)} -> #NAME?
A35: J | B35: ="EESWE"&A35 -> EESWEJ | C35: 10M | D35: estr | E35: IRS | F35: OIS | G35: {=DATEVALUE(_xll.bdp($B35&" Curncy",G$1))} -> #NAME? | H35: {=DATEVALUE(_xll.bdp($B35&" Curncy",H$1))} -> #NAME? | I35: {=_xll.bdp($B35&" Curncy",I$1)} -> #NAME?
A36: K | B36: ="EESWE"&A36 -> EESWEK | C36: 11M | D36: estr | E36: IRS | F36: OIS | G36: {=DATEVALUE(_xll.bdp($B36&" Curncy",G$1))} -> #NAME? | H36: {=DATEVALUE(_xll.bdp($B36&" Curncy",H$1))} -> #NAME? | I36: {=_xll.bdp($B36&" Curncy",I$1)} -> #NAME?
A37: 1 | B37: ="EESWE"&A37 -> EESWE1 | C37: 1Y | D37: estr | E37: IRS | F37: OIS | G37: {=DATEVALUE(_xll.bdp($B37&" Curncy",G$1))} -> #NAME? | H37: {=DATEVALUE(_xll.bdp($B37&" Curncy",H$1))} -> #NAME? | I37: {=_xll.bdp($B37&" Curncy",I$1)} -> #NAME?
A38: 2 | B38: ="EESWE"&A38 -> EESWE2 | C38: 2Y | D38: estr | E38: IRS | F38: OIS | G38: {=DATEVALUE(_xll.bdp($B38&" Curncy",G$1))} -> #NAME? | H38: {=DATEVALUE(_xll.bdp($B38&" Curncy",H$1))} -> #NAME? | I38: {=_xll.bdp($B38&" Curncy",I$1)} -> #NAME?
A39: 3 | B39: ="EESWE"&A39 -> EESWE3 | C39: 3Y | D39: estr | E39: IRS | F39: OIS | G39: {=DATEVALUE(_xll.bdp($B39&" Curncy",G$1))} -> #NAME? | H39: {=DATEVALUE(_xll.bdp($B39&" Curncy",H$1))} -> #NAME? | I39: {=_xll.bdp($B39&" Curncy",I$1)} -> #NAME?
A40: 4 | B40: ="EESWE"&A40 -> EESWE4 | C40: 4Y | D40: estr | E40: IRS | F40: OIS | G40: {=DATEVALUE(_xll.bdp($B40&" Curncy",G$1))} -> #NAME? | H40: {=DATEVALUE(_xll.bdp($B40&" Curncy",H$1))} -> #NAME? | I40: {=_xll.bdp($B40&" Curncy",I$1)} -> #NAME?
...
